<?xml version="1.0" encoding="utf-8"?>
<!--
  motion_mujoco_mjcf_4dof_arm_tall_SPEC.xml
  =======================================
  Tall-shoulder variant of motion_mujoco_mjcf_4dof_arm_SPEC.xml (shoulder_mount z = 1.60 m).
-->
<mujoco model="dart_robot_4dof_arm_TALL_SPEC">
  <compiler angle="degree" inertiafromgeom="true"/>

  <option timestep="0.001" gravity="0 0 -9.81"/>

  <default>
    <joint limited="true" damping="0.1"/>
    <geom type="capsule" condim="1" friction="0.6 0.005 0.0001"/>
  </default>

  <asset/>

  <worldbody>
    <body name="shoulder_mount" pos="0 0 1.60">
      <site name="shoulder_origin" pos="0 0 0" size="0.01"/>
      <body name="yaw_link" pos="0 0 0">
        <geom name="yaw_hub_geom" type="sphere" size="0.008" mass="0.02" rgba="0.3 0.3 0.3 0.3"/>
        <joint name="shoulder_yaw" type="hinge" axis="0 0 1" range="-55 55"/>
        <body name="upper_arm" pos="0 0 0">
          <joint name="shoulder" type="hinge" axis="0 1 0" range="-60 180"/>
          <geom name="upper_arm_geom" fromto="0 0 0 0.30 0 0" size="0.02" mass="2.1"/>
          <body name="forearm" pos="0.30 0 0">
            <joint name="elbow" type="hinge" axis="0 1 0" range="-145 0"/>
            <geom name="forearm_geom" fromto="0 0 0 0.26 0 0" size="0.018" mass="1.2"/>
            <body name="hand" pos="0.26 0 0">
              <joint name="wrist" type="hinge" axis="0 1 0" range="-70 70"/>
              <geom name="hand_geom" fromto="0 0 0 0.08 0 0" size="0.015" mass="0.4"/>
              <site name="release_site" pos="0.08 0 0" size="0.005" rgba="1 0 0 0.5"/>
            </body>
          </body>
        </body>
      </body>
    </body>
  </worldbody>

  <actuator>
    <motor name="tau_shoulder_yaw" joint="shoulder_yaw" gear="1" ctrllimited="true" ctrlrange="-55 55"/>
    <motor name="tau_shoulder" joint="shoulder" gear="1" ctrllimited="true" ctrlrange="-100 100"/>
    <motor name="tau_elbow" joint="elbow" gear="1" ctrllimited="true" ctrlrange="-70 70"/>
    <motor name="tau_wrist" joint="wrist" gear="1" ctrllimited="true" ctrlrange="-20 20"/>
  </actuator>

  <keyframe>
    <key name="cocked" qpos="0 -0.9599 -1.5708 -0.3491"/>
  </keyframe>
</mujoco>
